  Bad Request: /api/token/refresh/
3:53:30 AM web.1 |  Internal Server Error: /api/user/tests/
3:53:30 AM web.1 |  Traceback (most recent call last):
3:53:30 AM web.1 |    File "/home/lucas/.local/share/virtualenvs/GeneratorSprawdzianow-FRoXrxil/lib/python3.7/site-packages/django/db/backends/utils.py", line 84, in _execute
3:53:30 AM web.1 |      return self.cursor.execute(sql, params)
3:53:30 AM web.1 |  psycopg2.errors.UndefinedColumn: column authentication_testjson.user_id does not exist
3:53:30 AM web.1 |  LINE 1: ...on"."tasks", "authentication_testjson"."created", "authentic...
3:53:30 AM web.1 |                                                               ^
3:53:30 AM web.1 |  HINT:  Perhaps you meant to reference the column "authentication_testjson.user_id_id".
3:53:30 AM web.1 |  The above exception was the direct cause of the following exception:
3:53:30 AM web.1 |  Traceback (most recent call last):
3:53:30 AM web.1 |    File "/home/lucas/.local/share/virtualenvs/GeneratorSprawdzianow-FRoXrxil/lib/python3.7/site-packages/django/core/handlers/exception.py", line 47, in inner
3:53:30 AM web.1 |      response = get_response(request)
3:53:30 AM web.1 |    File "/home/lucas/.local/share/virtualenvs/GeneratorSprawdzianow-FRoXrxil/lib/python3.7/site-packages/django/core/handlers/base.py", line 179, in _get_response
3:53:30 AM web.1 |      response = wrapped_callback(request, *callback_args, **callback_kwargs)
3:53:30 AM web.1 |    File "/home/lucas/.local/share/virtualenvs/GeneratorSprawdzianow-FRoXrxil/lib/python3.7/site-packages/django/views/decorators/csrf.py", line 54, in wrapped_view
3:53:30 AM web.1 |      return view_func(*args, **kwargs)
3:53:30 AM web.1 |    File "/home/lucas/.local/share/virtualenvs/GeneratorSprawdzianow-FRoXrxil/lib/python3.7/site-packages/django/views/generic/base.py", line 70, in view
3:53:30 AM web.1 |      return self.dispatch(request, *args, **kwargs)
3:53:30 AM web.1 |    File "/home/lucas/.local/share/virtualenvs/GeneratorSprawdzianow-FRoXrxil/lib/python3.7/site-packages/rest_framework/views.py", line 509, in dispatch
3:53:30 AM web.1 |      response = self.handle_exception(exc)
3:53:30 AM web.1 |    File "/home/lucas/.local/share/virtualenvs/GeneratorSprawdzianow-FRoXrxil/lib/python3.7/site-packages/rest_framework/views.py", line 469, in handle_exception
3:53:30 AM web.1 |      self.raise_uncaught_exception(exc)
3:53:30 AM web.1 |    File "/home/lucas/.local/share/virtualenvs/GeneratorSprawdzianow-FRoXrxil/lib/python3.7/site-packages/rest_framework/views.py", line 480, in raise_uncaught_exception
3:53:30 AM web.1 |      raise exc
3:53:30 AM web.1 |    File "/home/lucas/.local/share/virtualenvs/GeneratorSprawdzianow-FRoXrxil/lib/python3.7/site-packages/rest_framework/views.py", line 506, in dispatch
3:53:30 AM web.1 |      response = handler(request, *args, **kwargs)
3:53:30 AM web.1 |    File "/home/lucas/PycharmProjects/GeneratorSprawdzianow/djsr/authentication/views.py", line 676, in get
3:53:30 AM web.1 |      return Response(serializer.data)
3:53:30 AM web.1 |    File "/home/lucas/.local/share/virtualenvs/GeneratorSprawdzianow-FRoXrxil/lib/python3.7/site-packages/rest_framework/serializers.py", line 745, in data
3:53:30 AM web.1 |      ret = super().data
3:53:30 AM web.1 |    File "/home/lucas/.local/share/virtualenvs/GeneratorSprawdzianow-FRoXrxil/lib/python3.7/site-packages/rest_framework/serializers.py", line 246, in data
3:53:30 AM web.1 |      self._data = self.to_representation(self.instance)
3:53:30 AM web.1 |    File "/home/lucas/.local/share/virtualenvs/GeneratorSprawdzianow-FRoXrxil/lib/python3.7/site-packages/rest_framework/serializers.py", line 664, in to_representation
3:53:30 AM web.1 |      self.child.to_representation(item) for item in iterable
3:53:30 AM web.1 |    File "/home/lucas/.local/share/virtualenvs/GeneratorSprawdzianow-FRoXrxil/lib/python3.7/site-packages/django/db/models/query.py", line 287, in __iter__
3:53:30 AM web.1 |      self._fetch_all()
3:53:30 AM web.1 |    File "/home/lucas/.local/share/virtualenvs/GeneratorSprawdzianow-FRoXrxil/lib/python3.7/site-packages/django/db/models/query.py", line 1308, in _fetch_all
3:53:30 AM web.1 |      self._result_cache = list(self._iterable_class(self))
3:53:30 AM web.1 |    File "/home/lucas/.local/share/virtualenvs/GeneratorSprawdzianow-FRoXrxil/lib/python3.7/site-packages/django/db/models/query.py", line 53, in __iter__
3:53:30 AM web.1 |      results = compiler.execute_sql(chunked_fetch=self.chunked_fetch, chunk_size=self.chunk_size)
3:53:30 AM web.1 |    File "/home/lucas/.local/share/virtualenvs/GeneratorSprawdzianow-FRoXrxil/lib/python3.7/site-packages/django/db/models/sql/compiler.py", line 1156, in execute_sql
3:53:30 AM web.1 |      cursor.execute(sql, params)
3:53:30 AM web.1 |    File "/home/lucas/.local/share/virtualenvs/GeneratorSprawdzianow-FRoXrxil/lib/python3.7/site-packages/django/db/backends/utils.py", line 98, in execute
3:53:30 AM web.1 |      return super().execute(sql, params)
3:53:30 AM web.1 |    File "/home/lucas/.local/share/virtualenvs/GeneratorSprawdzianow-FRoXrxil/lib/python3.7/site-packages/django/db/backends/utils.py", line 66, in execute
3:53:30 AM web.1 |      return self._execute_with_wrappers(sql, params, many=False, executor=self._execute)
3:53:30 AM web.1 |    File "/home/lucas/.local/share/virtualenvs/GeneratorSprawdzianow-FRoXrxil/lib/python3.7/site-packages/django/db/backends/utils.py", line 75, in _execute_with_wrappers
3:53:30 AM web.1 |      return executor(sql, params, many, context)
3:53:30 AM web.1 |    File "/home/lucas/.local/share/virtualenvs/GeneratorSprawdzianow-FRoXrxil/lib/python3.7/site-packages/django/db/backends/utils.py", line 84, in _execute
3:53:30 AM web.1 |      return self.cursor.execute(sql, params)
3:53:30 AM web.1 |    File "/home/lucas/.local/share/virtualenvs/GeneratorSprawdzianow-FRoXrxil/lib/python3.7/site-packages/django/db/utils.py", line 90, in __exit__
3:53:30 AM web.1 |      raise dj_exc_value.with_traceback(traceback) from exc_value
3:53:30 AM web.1 |    File "/home/lucas/.local/share/virtualenvs/GeneratorSprawdzianow-FRoXrxil/lib/python3.7/site-packages/django/db/backends/utils.py", line 84, in _execute
3:53:30 AM web.1 |      return self.cursor.execute(sql, params)
3:53:30 AM web.1 |  django.db.utils.ProgrammingError: column authentication_testjson.user_id does not exist
3:53:30 AM web.1 |  LINE 1: ...on"."tasks", "authentication_testjson"."created", "authentic...
3:53:30 AM web.1 |                                                               ^
3:53:30 AM web.1 |  HINT:  Perhaps you meant to reference the column "authentication_testjson.user_id_id".
3:53:46 AM web.1 |  Internal Server Error: /api/user/tests/
3:53:46 AM web.1 |  Traceback (most recent call last):
3:53:46 AM web.1 |    File "/home/lucas/.local/share/virtualenvs/GeneratorSprawdzianow-FRoXrxil/lib/python3.7/site-packages/django/db/backends/utils.py", line 84, in _execute
3:53:46 AM web.1 |      return self.cursor.execute(sql, params)
3:53:46 AM web.1 |  psycopg2.errors.UndefinedColumn: column authentication_testjson.user_id does not exist
3:53:46 AM web.1 |  LINE 1: ...on"."tasks", "authentication_testjson"."created", "authentic...
3:53:46 AM web.1 |                                                               ^
3:53:46 AM web.1 |  HINT:  Perhaps you meant to reference the column "authentication_testjson.user_id_id".
3:53:46 AM web.1 |  The above exception was the direct cause of the following exception:
3:53:46 AM web.1 |  Traceback (most recent call last):
3:53:46 AM web.1 |    File "/home/lucas/.local/share/virtualenvs/GeneratorSprawdzianow-FRoXrxil/lib/python3.7/site-packages/django/core/handlers/exception.py", line 47, in inner
3:53:46 AM web.1 |      response = get_response(request)
3:53:46 AM web.1 |    File "/home/lucas/.local/share/virtualenvs/GeneratorSprawdzianow-FRoXrxil/lib/python3.7/site-packages/django/core/handlers/base.py", line 179, in _get_response
3:53:46 AM web.1 |      response = wrapped_callback(request, *callback_args, **callback_kwargs)
3:53:46 AM web.1 |    File "/home/lucas/.local/share/virtualenvs/GeneratorSprawdzianow-FRoXrxil/lib/python3.7/site-packages/django/views/decorators/csrf.py", line 54, in wrapped_view
3:53:46 AM web.1 |      return view_func(*args, **kwargs)
3:53:46 AM web.1 |    File "/home/lucas/.local/share/virtualenvs/GeneratorSprawdzianow-FRoXrxil/lib/python3.7/site-packages/django/views/generic/base.py", line 70, in view
3:53:46 AM web.1 |      return self.dispatch(request, *args, **kwargs)
3:53:46 AM web.1 |    File "/home/lucas/.local/share/virtualenvs/GeneratorSprawdzianow-FRoXrxil/lib/python3.7/site-packages/rest_framework/views.py", line 509, in dispatch
3:53:46 AM web.1 |      response = self.handle_exception(exc)
3:53:46 AM web.1 |    File "/home/lucas/.local/share/virtualenvs/GeneratorSprawdzianow-FRoXrxil/lib/python3.7/site-packages/rest_framework/views.py", line 469, in handle_exception
3:53:46 AM web.1 |      self.raise_uncaught_exception(exc)
3:53:46 AM web.1 |    File "/home/lucas/.local/share/virtualenvs/GeneratorSprawdzianow-FRoXrxil/lib/python3.7/site-packages/rest_framework/views.py", line 480, in raise_uncaught_exception
3:53:46 AM web.1 |      raise exc
3:53:46 AM web.1 |    File "/home/lucas/.local/share/virtualenvs/GeneratorSprawdzianow-FRoXrxil/lib/python3.7/site-packages/rest_framework/views.py", line 506, in dispatch
3:53:46 AM web.1 |      response = handler(request, *args, **kwargs)
3:53:46 AM web.1 |    File "/home/lucas/PycharmProjects/GeneratorSprawdzianow/djsr/authentication/views.py", line 676, in get
3:53:46 AM web.1 |      return Response(serializer.data)
3:53:46 AM web.1 |    File "/home/lucas/.local/share/virtualenvs/GeneratorSprawdzianow-FRoXrxil/lib/python3.7/site-packages/rest_framework/serializers.py", line 745, in data
3:53:46 AM web.1 |      ret = super().data
3:53:46 AM web.1 |    File "/home/lucas/.local/share/virtualenvs/GeneratorSprawdzianow-FRoXrxil/lib/python3.7/site-packages/rest_framework/serializers.py", line 246, in data
3:53:46 AM web.1 |      self._data = self.to_representation(self.instance)
3:53:46 AM web.1 |    File "/home/lucas/.local/share/virtualenvs/GeneratorSprawdzianow-FRoXrxil/lib/python3.7/site-packages/rest_framework/serializers.py", line 664, in to_representation
3:53:46 AM web.1 |      self.child.to_representation(item) for item in iterable
3:53:46 AM web.1 |    File "/home/lucas/.local/share/virtualenvs/GeneratorSprawdzianow-FRoXrxil/lib/python3.7/site-packages/django/db/models/query.py", line 287, in __iter__
3:53:46 AM web.1 |      self._fetch_all()
3:53:46 AM web.1 |    File "/home/lucas/.local/share/virtualenvs/GeneratorSprawdzianow-FRoXrxil/lib/python3.7/site-packages/django/db/models/query.py", line 1308, in _fetch_all
3:53:46 AM web.1 |      self._result_cache = list(self._iterable_class(self))
3:53:46 AM web.1 |    File "/home/lucas/.local/share/virtualenvs/GeneratorSprawdzianow-FRoXrxil/lib/python3.7/site-packages/django/db/models/query.py", line 53, in __iter__
3:53:46 AM web.1 |      results = compiler.execute_sql(chunked_fetch=self.chunked_fetch, chunk_size=self.chunk_size)
3:53:46 AM web.1 |    File "/home/lucas/.local/share/virtualenvs/GeneratorSprawdzianow-FRoXrxil/lib/python3.7/site-packages/django/db/models/sql/compiler.py", line 1156, in execute_sql
3:53:46 AM web.1 |      cursor.execute(sql, params)
3:53:46 AM web.1 |    File "/home/lucas/.local/share/virtualenvs/GeneratorSprawdzianow-FRoXrxil/lib/python3.7/site-packages/django/db/backends/utils.py", line 98, in execute
3:53:46 AM web.1 |      return super().execute(sql, params)
3:53:46 AM web.1 |    File "/home/lucas/.local/share/virtualenvs/GeneratorSprawdzianow-FRoXrxil/lib/python3.7/site-packages/django/db/backends/utils.py", line 66, in execute
3:53:46 AM web.1 |      return self._execute_with_wrappers(sql, params, many=False, executor=self._execute)
3:53:46 AM web.1 |    File "/home/lucas/.local/share/virtualenvs/GeneratorSprawdzianow-FRoXrxil/lib/python3.7/site-packages/django/db/backends/utils.py", line 75, in _execute_with_wrappers
3:53:46 AM web.1 |      return executor(sql, params, many, context)
3:53:46 AM web.1 |    File "/home/lucas/.local/share/virtualenvs/GeneratorSprawdzianow-FRoXrxil/lib/python3.7/site-packages/django/db/backends/utils.py", line 84, in _execute
3:53:46 AM web.1 |      return self.cursor.execute(sql, params)
3:53:46 AM web.1 |    File "/home/lucas/.local/share/virtualenvs/GeneratorSprawdzianow-FRoXrxil/lib/python3.7/site-packages/django/db/utils.py", line 90, in __exit__
3:53:46 AM web.1 |      raise dj_exc_value.with_traceback(traceback) from exc_value
3:53:46 AM web.1 |    File "/home/lucas/.local/share/virtualenvs/GeneratorSprawdzianow-FRoXrxil/lib/python3.7/site-packages/django/db/backends/utils.py", line 84, in _execute
3:53:46 AM web.1 |      return self.cursor.execute(sql, params)
3:53:46 AM web.1 |  django.db.utils.ProgrammingError: column authentication_testjson.user_id does not exist
3:53:46 AM web.1 |  LINE 1: ...on"."tasks", "authentication_testjson"."created", "authentic...
3:53:46 AM web.1 |                                                               ^
3:53:46 AM web.1 |  HINT:  Perhaps you meant to reference the column "authentication_testjson.user_id_id".
3:54:00 AM web.1 |  Internal Server Error: /api/user/onetest/101
3:54:00 AM web.1 |  Traceback (most recent call last):
3:54:00 AM web.1 |    File "/home/lucas/.local/share/virtualenvs/GeneratorSprawdzianow-FRoXrxil/lib/python3.7/site-packages/django/db/backends/utils.py", line 84, in _execute
3:54:00 AM web.1 |      return self.cursor.execute(sql, params)
3:54:00 AM web.1 |  psycopg2.errors.UndefinedColumn: column authentication_testjson.user_id does not exist
3:54:00 AM web.1 |  LINE 1: ...on"."tasks", "authentication_testjson"."created", "authentic...
3:54:00 AM web.1 |                                                               ^
3:54:00 AM web.1 |  HINT:  Perhaps you meant to reference the column "authentication_testjson.user_id_id".
3:54:00 AM web.1 |  The above exception was the direct cause of the following exception:
3:54:00 AM web.1 |  Traceback (most recent call last):
3:54:00 AM web.1 |    File "/home/lucas/.local/share/virtualenvs/GeneratorSprawdzianow-FRoXrxil/lib/python3.7/site-packages/django/core/handlers/exception.py", line 47, in inner
3:54:00 AM web.1 |      response = get_response(request)
3:54:00 AM web.1 |    File "/home/lucas/.local/share/virtualenvs/GeneratorSprawdzianow-FRoXrxil/lib/python3.7/site-packages/django/core/handlers/base.py", line 179, in _get_response
3:54:00 AM web.1 |      response = wrapped_callback(request, *callback_args, **callback_kwargs)
3:54:00 AM web.1 |    File "/home/lucas/.local/share/virtualenvs/GeneratorSprawdzianow-FRoXrxil/lib/python3.7/site-packages/django/views/decorators/csrf.py", line 54, in wrapped_view
3:54:00 AM web.1 |      return view_func(*args, **kwargs)
3:54:00 AM web.1 |    File "/home/lucas/.local/share/virtualenvs/GeneratorSprawdzianow-FRoXrxil/lib/python3.7/site-packages/django/views/generic/base.py", line 70, in view
3:54:00 AM web.1 |      return self.dispatch(request, *args, **kwargs)
3:54:00 AM web.1 |    File "/home/lucas/.local/share/virtualenvs/GeneratorSprawdzianow-FRoXrxil/lib/python3.7/site-packages/rest_framework/views.py", line 509, in dispatch
3:54:00 AM web.1 |      response = self.handle_exception(exc)
3:54:00 AM web.1 |    File "/home/lucas/.local/share/virtualenvs/GeneratorSprawdzianow-FRoXrxil/lib/python3.7/site-packages/rest_framework/views.py", line 469, in handle_exception
3:54:00 AM web.1 |      self.raise_uncaught_exception(exc)
3:54:00 AM web.1 |    File "/home/lucas/.local/share/virtualenvs/GeneratorSprawdzianow-FRoXrxil/lib/python3.7/site-packages/rest_framework/views.py", line 480, in raise_uncaught_exception
3:54:00 AM web.1 |      raise exc
3:54:00 AM web.1 |    File "/home/lucas/.local/share/virtualenvs/GeneratorSprawdzianow-FRoXrxil/lib/python3.7/site-packages/rest_framework/views.py", line 506, in dispatch
3:54:00 AM web.1 |      response = handler(request, *args, **kwargs)
3:54:00 AM web.1 |    File "/home/lucas/PycharmProjects/GeneratorSprawdzianow/djsr/authentication/views.py", line 687, in get
3:54:00 AM web.1 |      return Response(serializer.data)
3:54:00 AM web.1 |    File "/home/lucas/.local/share/virtualenvs/GeneratorSprawdzianow-FRoXrxil/lib/python3.7/site-packages/rest_framework/serializers.py", line 745, in data
3:54:00 AM web.1 |      ret = super().data
3:54:00 AM web.1 |    File "/home/lucas/.local/share/virtualenvs/GeneratorSprawdzianow-FRoXrxil/lib/python3.7/site-packages/rest_framework/serializers.py", line 246, in data
3:54:00 AM web.1 |      self._data = self.to_representation(self.instance)
3:54:00 AM web.1 |    File "/home/lucas/.local/share/virtualenvs/GeneratorSprawdzianow-FRoXrxil/lib/python3.7/site-packages/rest_framework/serializers.py", line 664, in to_representation
3:54:00 AM web.1 |      self.child.to_representation(item) for item in iterable
3:54:00 AM web.1 |    File "/home/lucas/.local/share/virtualenvs/GeneratorSprawdzianow-FRoXrxil/lib/python3.7/site-packages/django/db/models/query.py", line 287, in __iter__
3:54:00 AM web.1 |      self._fetch_all()
3:54:00 AM web.1 |    File "/home/lucas/.local/share/virtualenvs/GeneratorSprawdzianow-FRoXrxil/lib/python3.7/site-packages/django/db/models/query.py", line 1308, in _fetch_all
3:54:00 AM web.1 |      self._result_cache = list(self._iterable_class(self))
3:54:00 AM web.1 |    File "/home/lucas/.local/share/virtualenvs/GeneratorSprawdzianow-FRoXrxil/lib/python3.7/site-packages/django/db/models/query.py", line 53, in __iter__
3:54:00 AM web.1 |      results = compiler.execute_sql(chunked_fetch=self.chunked_fetch, chunk_size=self.chunk_size)
3:54:00 AM web.1 |    File "/home/lucas/.local/share/virtualenvs/GeneratorSprawdzianow-FRoXrxil/lib/python3.7/site-packages/django/db/models/sql/compiler.py", line 1156, in execute_sql
3:54:00 AM web.1 |      cursor.execute(sql, params)
3:54:00 AM web.1 |    File "/home/lucas/.local/share/virtualenvs/GeneratorSprawdzianow-FRoXrxil/lib/python3.7/site-packages/django/db/backends/utils.py", line 98, in execute
3:54:00 AM web.1 |      return super().execute(sql, params)
3:54:00 AM web.1 |    File "/home/lucas/.local/share/virtualenvs/GeneratorSprawdzianow-FRoXrxil/lib/python3.7/site-packages/django/db/backends/utils.py", line 66, in execute
3:54:00 AM web.1 |      return self._execute_with_wrappers(sql, params, many=False, executor=self._execute)
3:54:00 AM web.1 |    File "/home/lucas/.local/share/virtualenvs/GeneratorSprawdzianow-FRoXrxil/lib/python3.7/site-packages/django/db/backends/utils.py", line 75, in _execute_with_wrappers
3:54:00 AM web.1 |      return executor(sql, params, many, context)
3:54:00 AM web.1 |    File "/home/lucas/.local/share/virtualenvs/GeneratorSprawdzianow-FRoXrxil/lib/python3.7/site-packages/django/db/backends/utils.py", line 84, in _execute
3:54:00 AM web.1 |      return self.cursor.execute(sql, params)
3:54:00 AM web.1 |    File "/home/lucas/.local/share/virtualenvs/GeneratorSprawdzianow-FRoXrxil/lib/python3.7/site-packages/django/db/utils.py", line 90, in __exit__
3:54:00 AM web.1 |      raise dj_exc_value.with_traceback(traceback) from exc_value
3:54:00 AM web.1 |    File "/home/lucas/.local/share/virtualenvs/GeneratorSprawdzianow-FRoXrxil/lib/python3.7/site-packages/django/db/backends/utils.py", line 84, in _execute
3:54:00 AM web.1 |      return self.cursor.execute(sql, params)
3:54:00 AM web.1 |  django.db.utils.ProgrammingError: column authentication_testjson.user_id does not exist
3:54:00 AM web.1 |  LINE 1: ...on"."tasks", "authentication_testjson"."created", "authentic...
3:54:00 AM web.1 |                                                               ^
3:54:00 AM web.1 |  HINT:  Perhaps you meant to reference the column "authentication_testjson.user_id_id".
3:54:06 AM web.1 |  Internal Server Error: /api/user/onetest/101
3:54:06 AM web.1 |  Traceback (most recent call last):
3:54:06 AM web.1 |    File "/home/lucas/.local/share/virtualenvs/GeneratorSprawdzianow-FRoXrxil/lib/python3.7/site-packages/django/db/backends/utils.py", line 84, in _execute
3:54:06 AM web.1 |      return self.cursor.execute(sql, params)
3:54:06 AM web.1 |  psycopg2.errors.UndefinedColumn: column authentication_testjson.user_id does not exist
3:54:06 AM web.1 |  LINE 1: ...on"."tasks", "authentication_testjson"."created", "authentic...
3:54:06 AM web.1 |                                                               ^
3:54:06 AM web.1 |  HINT:  Perhaps you meant to reference the column "authentication_testjson.user_id_id".
3:54:06 AM web.1 |  The above exception was the direct cause of the following exception:
3:54:06 AM web.1 |  Traceback (most recent call last):
3:54:06 AM web.1 |    File "/home/lucas/.local/share/virtualenvs/GeneratorSprawdzianow-FRoXrxil/lib/python3.7/site-packages/django/core/handlers/exception.py", line 47, in inner
3:54:06 AM web.1 |      response = get_response(request)
3:54:06 AM web.1 |    File "/home/lucas/.local/share/virtualenvs/GeneratorSprawdzianow-FRoXrxil/lib/python3.7/site-packages/django/core/handlers/base.py", line 179, in _get_response
3:54:06 AM web.1 |      response = wrapped_callback(request, *callback_args, **callback_kwargs)
3:54:06 AM web.1 |    File "/home/lucas/.local/share/virtualenvs/GeneratorSprawdzianow-FRoXrxil/lib/python3.7/site-packages/django/views/decorators/csrf.py", line 54, in wrapped_view
3:54:06 AM web.1 |      return view_func(*args, **kwargs)
3:54:06 AM web.1 |    File "/home/lucas/.local/share/virtualenvs/GeneratorSprawdzianow-FRoXrxil/lib/python3.7/site-packages/django/views/generic/base.py", line 70, in view
3:54:06 AM web.1 |      return self.dispatch(request, *args, **kwargs)
3:54:06 AM web.1 |    File "/home/lucas/.local/share/virtualenvs/GeneratorSprawdzianow-FRoXrxil/lib/python3.7/site-packages/rest_framework/views.py", line 509, in dispatch
3:54:06 AM web.1 |      response = self.handle_exception(exc)
3:54:06 AM web.1 |    File "/home/lucas/.local/share/virtualenvs/GeneratorSprawdzianow-FRoXrxil/lib/python3.7/site-packages/rest_framework/views.py", line 469, in handle_exception
3:54:06 AM web.1 |      self.raise_uncaught_exception(exc)
3:54:06 AM web.1 |    File "/home/lucas/.local/share/virtualenvs/GeneratorSprawdzianow-FRoXrxil/lib/python3.7/site-packages/rest_framework/views.py", line 480, in raise_uncaught_exception
3:54:06 AM web.1 |      raise exc
3:54:06 AM web.1 |    File "/home/lucas/.local/share/virtualenvs/GeneratorSprawdzianow-FRoXrxil/lib/python3.7/site-packages/rest_framework/views.py", line 506, in dispatch
3:54:06 AM web.1 |      response = handler(request, *args, **kwargs)
3:54:06 AM web.1 |    File "/home/lucas/PycharmProjects/GeneratorSprawdzianow/djsr/authentication/views.py", line 687, in get
3:54:06 AM web.1 |      return Response(serializer.data)
3:54:06 AM web.1 |    File "/home/lucas/.local/share/virtualenvs/GeneratorSprawdzianow-FRoXrxil/lib/python3.7/site-packages/rest_framework/serializers.py", line 745, in data
3:54:06 AM web.1 |      ret = super().data
3:54:06 AM web.1 |    File "/home/lucas/.local/share/virtualenvs/GeneratorSprawdzianow-FRoXrxil/lib/python3.7/site-packages/rest_framework/serializers.py", line 246, in data
3:54:06 AM web.1 |      self._data = self.to_representation(self.instance)
3:54:06 AM web.1 |    File "/home/lucas/.local/share/virtualenvs/GeneratorSprawdzianow-FRoXrxil/lib/python3.7/site-packages/rest_framework/serializers.py", line 664, in to_representation
3:54:06 AM web.1 |      self.child.to_representation(item) for item in iterable
3:54:06 AM web.1 |    File "/home/lucas/.local/share/virtualenvs/GeneratorSprawdzianow-FRoXrxil/lib/python3.7/site-packages/django/db/models/query.py", line 287, in __iter__
3:54:06 AM web.1 |      self._fetch_all()
3:54:06 AM web.1 |    File "/home/lucas/.local/share/virtualenvs/GeneratorSprawdzianow-FRoXrxil/lib/python3.7/site-packages/django/db/models/query.py", line 1308, in _fetch_all
3:54:06 AM web.1 |      self._result_cache = list(self._iterable_class(self))
3:54:06 AM web.1 |    File "/home/lucas/.local/share/virtualenvs/GeneratorSprawdzianow-FRoXrxil/lib/python3.7/site-packages/django/db/models/query.py", line 53, in __iter__
3:54:06 AM web.1 |      results = compiler.execute_sql(chunked_fetch=self.chunked_fetch, chunk_size=self.chunk_size)
3:54:06 AM web.1 |    File "/home/lucas/.local/share/virtualenvs/GeneratorSprawdzianow-FRoXrxil/lib/python3.7/site-packages/django/db/models/sql/compiler.py", line 1156, in execute_sql
3:54:06 AM web.1 |      cursor.execute(sql, params)
3:54:06 AM web.1 |    File "/home/lucas/.local/share/virtualenvs/GeneratorSprawdzianow-FRoXrxil/lib/python3.7/site-packages/django/db/backends/utils.py", line 98, in execute
3:54:06 AM web.1 |      return super().execute(sql, params)
3:54:06 AM web.1 |    File "/home/lucas/.local/share/virtualenvs/GeneratorSprawdzianow-FRoXrxil/lib/python3.7/site-packages/django/db/backends/utils.py", line 66, in execute
3:54:06 AM web.1 |      return self._execute_with_wrappers(sql, params, many=False, executor=self._execute)
3:54:06 AM web.1 |    File "/home/lucas/.local/share/virtualenvs/GeneratorSprawdzianow-FRoXrxil/lib/python3.7/site-packages/django/db/backends/utils.py", line 75, in _execute_with_wrappers
3:54:06 AM web.1 |      return executor(sql, params, many, context)
3:54:06 AM web.1 |    File "/home/lucas/.local/share/virtualenvs/GeneratorSprawdzianow-FRoXrxil/lib/python3.7/site-packages/django/db/backends/utils.py", line 84, in _execute
3:54:06 AM web.1 |      return self.cursor.execute(sql, params)
3:54:06 AM web.1 |    File "/home/lucas/.local/share/virtualenvs/GeneratorSprawdzianow-FRoXrxil/lib/python3.7/site-packages/django/db/utils.py", line 90, in __exit__
3:54:06 AM web.1 |      raise dj_exc_value.with_traceback(traceback) from exc_value
3:54:06 AM web.1 |    File "/home/lucas/.local/share/virtualenvs/GeneratorSprawdzianow-FRoXrxil/lib/python3.7/site-packages/django/db/backends/utils.py", line 84, in _execute
3:54:06 AM web.1 |      return self.cursor.execute(sql, params)
3:54:06 AM web.1 |  django.db.utils.ProgrammingError: column authentication_testjson.user_id does not exist
3:54:06 AM web.1 |  LINE 1: ...on"."tasks", "authentication_testjson"."created", "authentic...
3:54:06 AM web.1 |                                                               ^
3:54:06 AM web.1 |  HINT:  Perhaps you meant to reference the column "authentication_testjson.user_id_id".
3:54:10 AM web.1 |  Internal Server Error: /api/user/onetest/101
3:54:10 AM web.1 |  Traceback (most recent call last):
3:54:10 AM web.1 |    File "/home/lucas/.local/share/virtualenvs/GeneratorSprawdzianow-FRoXrxil/lib/python3.7/site-packages/django/db/backends/utils.py", line 84, in _execute
3:54:10 AM web.1 |      return self.cursor.execute(sql, params)
3:54:10 AM web.1 |  psycopg2.errors.UndefinedColumn: column authentication_testjson.user_id does not exist
3:54:10 AM web.1 |  LINE 1: ...on"."tasks", "authentication_testjson"."created", "authentic...
3:54:10 AM web.1 |                                                               ^
3:54:10 AM web.1 |  HINT:  Perhaps you meant to reference the column "authentication_testjson.user_id_id".
3:54:10 AM web.1 |  The above exception was the direct cause of the following exception:
3:54:10 AM web.1 |  Traceback (most recent call last):
3:54:10 AM web.1 |    File "/home/lucas/.local/share/virtualenvs/GeneratorSprawdzianow-FRoXrxil/lib/python3.7/site-packages/django/core/handlers/exception.py", line 47, in inner
3:54:10 AM web.1 |      response = get_response(request)
3:54:10 AM web.1 |    File "/home/lucas/.local/share/virtualenvs/GeneratorSprawdzianow-FRoXrxil/lib/python3.7/site-packages/django/core/handlers/base.py", line 179, in _get_response
3:54:10 AM web.1 |      response = wrapped_callback(request, *callback_args, **callback_kwargs)
3:54:10 AM web.1 |    File "/home/lucas/.local/share/virtualenvs/GeneratorSprawdzianow-FRoXrxil/lib/python3.7/site-packages/django/views/decorators/csrf.py", line 54, in wrapped_view
3:54:10 AM web.1 |      return view_func(*args, **kwargs)
3:54:10 AM web.1 |    File "/home/lucas/.local/share/virtualenvs/GeneratorSprawdzianow-FRoXrxil/lib/python3.7/site-packages/django/views/generic/base.py", line 70, in view
3:54:10 AM web.1 |      return self.dispatch(request, *args, **kwargs)
3:54:10 AM web.1 |    File "/home/lucas/.local/share/virtualenvs/GeneratorSprawdzianow-FRoXrxil/lib/python3.7/site-packages/rest_framework/views.py", line 509, in dispatch
3:54:10 AM web.1 |      response = self.handle_exception(exc)
3:54:10 AM web.1 |    File "/home/lucas/.local/share/virtualenvs/GeneratorSprawdzianow-FRoXrxil/lib/python3.7/site-packages/rest_framework/views.py", line 469, in handle_exception
3:54:10 AM web.1 |      self.raise_uncaught_exception(exc)
3:54:10 AM web.1 |    File "/home/lucas/.local/share/virtualenvs/GeneratorSprawdzianow-FRoXrxil/lib/python3.7/site-packages/rest_framework/views.py", line 480, in raise_uncaught_exception
3:54:10 AM web.1 |      raise exc
3:54:10 AM web.1 |    File "/home/lucas/.local/share/virtualenvs/GeneratorSprawdzianow-FRoXrxil/lib/python3.7/site-packages/rest_framework/views.py", line 506, in dispatch
3:54:10 AM web.1 |      response = handler(request, *args, **kwargs)
3:54:10 AM web.1 |    File "/home/lucas/PycharmProjects/GeneratorSprawdzianow/djsr/authentication/views.py", line 687, in get
3:54:10 AM web.1 |      return Response(serializer.data)
3:54:10 AM web.1 |    File "/home/lucas/.local/share/virtualenvs/GeneratorSprawdzianow-FRoXrxil/lib/python3.7/site-packages/rest_framework/serializers.py", line 745, in data
3:54:10 AM web.1 |      ret = super().data
3:54:10 AM web.1 |    File "/home/lucas/.local/share/virtualenvs/GeneratorSprawdzianow-FRoXrxil/lib/python3.7/site-packages/rest_framework/serializers.py", line 246, in data
3:54:10 AM web.1 |      self._data = self.to_representation(self.instance)
3:54:10 AM web.1 |    File "/home/lucas/.local/share/virtualenvs/GeneratorSprawdzianow-FRoXrxil/lib/python3.7/site-packages/rest_framework/serializers.py", line 664, in to_representation
3:54:10 AM web.1 |      self.child.to_representation(item) for item in iterable
3:54:10 AM web.1 |    File "/home/lucas/.local/share/virtualenvs/GeneratorSprawdzianow-FRoXrxil/lib/python3.7/site-packages/django/db/models/query.py", line 287, in __iter__
3:54:10 AM web.1 |      self._fetch_all()
3:54:10 AM web.1 |    File "/home/lucas/.local/share/virtualenvs/GeneratorSprawdzianow-FRoXrxil/lib/python3.7/site-packages/django/db/models/query.py", line 1308, in _fetch_all
3:54:10 AM web.1 |      self._result_cache = list(self._iterable_class(self))
3:54:10 AM web.1 |    File "/home/lucas/.local/share/virtualenvs/GeneratorSprawdzianow-FRoXrxil/lib/python3.7/site-packages/django/db/models/query.py", line 53, in __iter__
3:54:10 AM web.1 |      results = compiler.execute_sql(chunked_fetch=self.chunked_fetch, chunk_size=self.chunk_size)
3:54:10 AM web.1 |    File "/home/lucas/.local/share/virtualenvs/GeneratorSprawdzianow-FRoXrxil/lib/python3.7/site-packages/django/db/models/sql/compiler.py", line 1156, in execute_sql
3:54:10 AM web.1 |      cursor.execute(sql, params)
3:54:10 AM web.1 |    File "/home/lucas/.local/share/virtualenvs/GeneratorSprawdzianow-FRoXrxil/lib/python3.7/site-packages/django/db/backends/utils.py", line 98, in execute
3:54:10 AM web.1 |      return super().execute(sql, params)
3:54:10 AM web.1 |    File "/home/lucas/.local/share/virtualenvs/GeneratorSprawdzianow-FRoXrxil/lib/python3.7/site-packages/django/db/backends/utils.py", line 66, in execute
3:54:10 AM web.1 |      return self._execute_with_wrappers(sql, params, many=False, executor=self._execute)
3:54:10 AM web.1 |    File "/home/lucas/.local/share/virtualenvs/GeneratorSprawdzianow-FRoXrxil/lib/python3.7/site-packages/django/db/backends/utils.py", line 75, in _execute_with_wrappers
3:54:10 AM web.1 |      return executor(sql, params, many, context)
3:54:10 AM web.1 |    File "/home/lucas/.local/share/virtualenvs/GeneratorSprawdzianow-FRoXrxil/lib/python3.7/site-packages/django/db/backends/utils.py", line 84, in _execute
3:54:10 AM web.1 |      return self.cursor.execute(sql, params)
3:54:10 AM web.1 |    File "/home/lucas/.local/share/virtualenvs/GeneratorSprawdzianow-FRoXrxil/lib/python3.7/site-packages/django/db/utils.py", line 90, in __exit__
3:54:10 AM web.1 |      raise dj_exc_value.with_traceback(traceback) from exc_value
3:54:10 AM web.1 |    File "/home/lucas/.local/share/virtualenvs/GeneratorSprawdzianow-FRoXrxil/lib/python3.7/site-packages/django/db/backends/utils.py", line 84, in _execute
3:54:10 AM web.1 |      return self.cursor.execute(sql, params)
3:54:10 AM web.1 |  django.db.utils.ProgrammingError: column authentication_testjson.user_id does not exist
3:54:10 AM web.1 |  LINE 1: ...on"."tasks", "authentication_testjson"."created", "authentic...
3:54:10 AM web.1 |                                                               ^
3:54:10 AM web.1 |  HINT:  Perhaps you meant to reference the column "authentication_testjson.user_id_id".
